Workbook
Name aaaaaaaaa: INDIRECT(ADDRESS(Questionario!XFB1,COLUMN(Questionario!XEY$1),4,))
Name Range_1: Appoggio!$A$11:$B$13
Name Range_2: Appoggio!$A$17:$B$18
Name Range_validi: Appoggio!$A$4:$A$5

Sheet Introduzione
B3: CLUSIT, associazione Italiana per la Sicurezza Informatica, considerando le notevoli problematiche ed inefficienze che interessano questo ambito, ha attivato un gruppo di lavoro per redigere un questionario di riferimento, a supporto universale delle organizzazioni di ogni tipo, per la selezione di fornitori ICT di prodotti e servizi, al fine di permettere di verificare agevolmente il loro grado di sicurezza delle informazioni/sicurezza ICT/cybersecurity da loro offerto e, attraverso le risposte, dare dimostrazione dei requisiti applicabili in conformità alle best practice di settore e in linea con la strategia dell’organizzazione.
B5: Il questionario riportato nel foglio successivo si articola in 48 temi collegati a domande a risposta chiusa e multipla, che mirano a verificare i principali requisiti previsti da ISO/IEC 27001 (Sistema di Gestione per la Sicurezza delle Informazioni) e FNCS (Framework Nazionale di Cyber Security) applicabili a fornitori di prodotti e servizi ICT senza tuttavia entrare nel merito delle specifiche forniture. L'organizzazione, una volta deciso quali temi proporre (idealmente tutti ma si può optare per utilizzarne solo un sottoinsieme), e ricevuto il questionario compilato da parte del fornitore, sarà in grado di individuare i punti di debolezza/non conformità e, conseguentemente, richiedere le necessarie azioni sul fornitore in modo tale da garantire la propria cybersecurity.
B7: Il foglio del questionario è stato organizzato nelle seguenti colonne: - SEZIONE: è un'area che raggruppa temi e domande sullo stesso ambito. Sono previste le aree di GESTIONE DELLA SICUREZZA, SICUREZZA IT e SICUREZZA FISICA - CODICE: è un codice identificativo unico del tema formato da 3 lettere per l'area, un punto di separazione e due cifre per un numero progressivo - TEMA: è il testo descrittivo del tema - SOTTOINSIEME DOMANDE APPLICABILE A ...: colonne che indicano se la domanda è ritenuta parte di un sottoinsieme applicabile per esempio ai fornitori di prodotti ICT, di servizi ICT o altro - SELEZIONE DOMANDA: pilota l'inclusione o l'esclusione della domanda nel questionario e nel computo dei risultati derivanti dalla sua compilazione - RIFERIMENTI ISO/IEC 27001: è il requisito o il controllo della norma ISO/IEC 27001:2022 richiamato dalla risposta. Se questa è selezionata è plausibile presumere che il requisito o controllo sia almeno in parte attuato/implementato - RIFERIMENTI FNCS 2 e 2.1: è il requisito o il controllo del Framework Nazionale di Cyber Security richiamato dalla risposta. Se questa è selezionata è plausibile presumere che il requisito o controllo sia almeno in parte attuato/implementato - DOMANDA: è la domanda posta al fornitore - RISPOSTA DEL FORNITORE: è la risposta data alla domanda - NOTE / REMEDIATION / AZIONI IN CORSO: è un campo libero in cui si può richiedere di inserire dettagli ulteriori in ogni caso oppure solo laddove le risposte siano negative, indicando eventuali azioni in corso
B9: Il foglio dei risultati riepiloga il risultato della compilazione rispetto alle domande selezionate utilizzando un calcolo a doppia pesatura (delle domande e dei temi) e ritornando un punteggio pari al 100% in caso tutte le domande selezionate abbiano ricevuto risposta positiva, o proporzionalmente decrementale diversamente.
B11: Rispetto alla precedente versione 1.0 del questionario sono state introdotte le domande a risposta chiusa, la pesatura delle domande e dei temi e l'algoritmo di calcolo dei risultati oltre ad essere state corrette alcune imprecisioni. Rispetto alla precedente versione 2.0 del questionario è stata aggiunta una mappatura alla versione aggiornata del Framework Nazionale di Cyber Security. Rispetto alla precedente versione 2.1 del questionario sono stati coperti i requisiti del FNCS richiamati nell'ambito del PSNC e di quello legato a NIS2 ed è stata elaborata una versione in lingua inglese.
B13: Il questionario può essere liberamente utilizzato nel rispetto dei limiti posti dalla licenza Creative Commons CC BY-SA (https://creativecommons.org/licenses/by-sa/4.0/deed.it). Questa licenza permette a chiunque di usare questo prodotto per crearne una sua evoluzione a condizione che citi gli autori originali riportando la nostra URL http://www.clusit.it e utilizzi a sua volta lo stesso tipo di licenza:
B16: CLUSIT ringrazia per la partecipazione ai lavori di stesura della presente versione del questionario: Giovanni BELLUZZO Giancarlo BUTTI Fabio GUASCONI (Coordinatore) Roberto OBIALERO Massimiliano PERRONE Alessandro VALLEGA
B17: e per le precedenti versioni ringrazia anche: Elenio DURSI Federica Maria Rita LIVELLI Davide MANCONI Andrea RUI Sofia SCOZZARI Claudio TELMON

Sheet Questionario
A1: SEZIONE | B1: CODICE | C1: TEMA | D1: SOTTOINSIEME DOMANDE APPLICABILE A: | F1: SELEZIONE DOMANDA | G1: SELEZIONE TEMA | H1: RIFERIMENTI | K1: Peso Tema | L1: Peso Tema sel | M1: Peso Domanda | N1: Peso domanda sel | O1: Range Risposta | P1: (prima riga del tema) | Q1: Valore Risposta | R1: Valore Risposta Pesato | S1: Valore Risposta Pesato anche con il peso della domanda | T1: Grado di copertura del tema (Risposta) | U1: Grado di copertura del tema | V1: Peso Tema (Riportato) | W1: Utilizzato per parametrizzare la convalida delle risposte in colonna P | X1: DOMANDA | Y1: Risposta del fornitore | Z1: NOTE / REMEDIATION / AZIONI IN CORSO
D2: Servizi ICT | E2: Prodotti ICT (SW/HW) | H2: ISO/IEC 27001 | I2: FNCS 2 | J2: FNCS 2.1
A3: GESTIONE DELLA SICUREZZA | B3: GSI.01 | C3: Politica di alto livello che tratta la cybersecurity / sicurezza delle informazioni / sicurezza informatica | D3: ✔ | E3: ✔ | F3: ✔ | G3: =IF(L3>0,"✔","") -> ✔ | H3: 5.2 | I3: ID.GV-1 | J3: GV.PO-01 GV.PO-02 | K3: 2 | L3: =IF(COUNTA(F3:F7)<>0,K3,0) -> 2 | M3: 2 | N3: =IF(F3<>"",M3,0) -> 2 | O3: Range_1 | P3: {=IF(F3<>"",SUMPRODUCT(MAX((INDIRECT(ADDRESS(1,COLUMN(K$1),2) &":"& ADDRESS(ROW(),COLUMN(K$1),4))<>"")*(ROW(INDIRECT(ADDRESS(1,COLUMN(K$1),2) &":"& ADDRESS(ROW(),COLUMN(K$1),4)))))),239)} -> 3 | Q3: =IF(Y3<>"",VLOOKUP(Y3,INDIRECT(O3),2,0),"") | R3: =IF(Q3<>"",IF(F3<>"",Q3*M3,0),"") | S3: =IF(R3<>"",IF(R3<>0,R3*INDIRECT(ADDRESS(P3,COLUMN(K$1),4,)),0),"") | T3: =IF(R3<>"",R3/SUMIFS(M$3:M$253,P$3:P$253,P3),"") | U3: =IF(R3<>"",SUMIFS(T$3:T$253,P$3:P$253,P3),"") | V3: =IFERROR(INDEX(K:K,P3),0) -> 2 | W3: =ADDRESS(ROW(INDIRECT(O3)),COLUMN(INDIRECT(O3)),1,1,"Appoggio")&":"&ADDRESS(ROW(INDIRECT(O3))+ROWS(INDIRECT(O3))-1,COLUMN(INDIRECT(O3)),1,1) -> Appoggio!$A$11:$A$13 | X3: E' inclusiva di obiettivi e principi?
D4: ✔ | E4: ✔ | F4: ✔ | M4: 1 | N4: =IF(F4<>"",M4,0) -> 1 | O4: Range_1 | P4: {=IF(F4<>"",SUMPRODUCT(MAX((INDIRECT(ADDRESS(1,COLUMN(K$1),2) &":"& ADDRESS(ROW(),COLUMN(K$1),4))<>"")*(ROW(INDIRECT(ADDRESS(1,COLUMN(K$1),2) &":"& ADDRESS(ROW(),COLUMN(K$1),4)))))),239)} -> 3 | Q4: =IF(Y4<>"",VLOOKUP(Y4,INDIRECT(O4),2,0),"") | R4: =IF(Q4<>"",IF(F4<>"",Q4*M4,0),"") | S4: =IF(R4<>"",IF(R4<>0,R4*INDIRECT(ADDRESS(P4,COLUMN(K$1),4,)),0),"") | T4: =IF(R4<>"",R4/SUMIFS(M$3:M$253,P$3:P$253,P4),"") | U4: =IF(R4<>"",SUMIFS(T$3:T$253,P$3:P$253,P4),"") | V4: =IFERROR(INDEX(K:K,P4),0) -> 2 | W4: =ADDRESS(ROW(INDIRECT(O4)),COLUMN(INDIRECT(O4)),1,1,"Appoggio")&":"&ADDRESS(ROW(INDIRECT(O4))+ROWS(INDIRECT(O4))-1,COLUMN(INDIRECT(O4)),1,1) -> Appoggio!$A$11:$A$13 | X4: E' approvata dall'alta direzione
D5: ✔ | E5: ✔ | F5: ✔ | M5: 3 | N5: =IF(F5<>"",M5,0) -> 3 | O5: Range_1 | P5: {=IF(F5<>"",SUMPRODUCT(MAX((INDIRECT(ADDRESS(1,COLUMN(K$1),2) &":"& ADDRESS(ROW(),COLUMN(K$1),4))<>"")*(ROW(INDIRECT(ADDRESS(1,COLUMN(K$1),2) &":"& ADDRESS(ROW(),COLUMN(K$1),4)))))),239)} -> 3 | Q5: =IF(Y5<>"",VLOOKUP(Y5,INDIRECT(O5),2,0),"") | R5: =IF(Q5<>"",IF(F5<>"",Q5*M5,0),"") | S5: =IF(R5<>"",IF(R5<>0,R5*INDIRECT(ADDRESS(P5,COLUMN(K$1),4,)),0),"") | T5: =IF(R5<>"",R5/SUMIFS(M$3:M$253,P$3:P$253,P5),"") | U5: =IF(R5<>"",SUMIFS(T$3:T$253,P$3:P$253,P5),"") | V5: =IFERROR(INDEX(K:K,P5),0) -> 2 | W5: =ADDRESS(ROW(INDIRECT(O5)),COLUMN(INDIRECT(O5)),1,1,"Appoggio")&":"&ADDRESS(ROW(INDIRECT(O5))+ROWS(INDIRECT(O5))-1,COLUMN(INDIRECT(O5)),1,1) -> Appoggio!$A$11:$A$13 | X5: Viene resa disponibile a tutti i soggetti interni ed esterni rilevanti?
D6: ✔ | E6: ✔ | F6: ✔ | M6: 1 | N6: =IF(F6<>"",M6,0) -> 1 | O6: Range_2 | P6: {=IF(F6<>"",SUMPRODUCT(MAX((INDIRECT(ADDRESS(1,COLUMN(K$1),2) &":"& ADDRESS(ROW(),COLUMN(K$1),4))<>"")*(ROW(INDIRECT(ADDRESS(1,COLUMN(K$1),2) &":"& ADDRESS(ROW(),COLUMN(K$1),4)))))),239)} -> 3 | Q6: =IF(Y6<>"",VLOOKUP(Y6,INDIRECT(O6),2,0),"") | R6: =IF(Q6<>"",IF(F6<>"",Q6*M6,0),"") | S6: =IF(R6<>"",IF(R6<>0,R6*INDIRECT(ADDRESS(P6,COLUMN(K$1),4,)),0),"") | T6: =IF(R6<>"",R6/SUMIFS(M$3:M$253,P$3:P$253,P6),"") | U6: =IF(R6<>"",SUMIFS(T$3:T$253,P$3:P$253,P6),"") | V6: =IFERROR(INDEX(K:K,P6),0) -> 2 | W6: =ADDRESS(ROW(INDIRECT(O6)),COLUMN(INDIRECT(O6)),1,1,"Appoggio")&":"&ADDRESS(ROW(INDIRECT(O6))+ROWS(INDIRECT(O6))-1,COLUMN(INDIRECT(O6)),1,1) -> Appoggio!$A$17:$A$18 | X6: Viene aggiornata almeno annualmente?
D7: ✔ | E7: ✔ | F7: ✔ | M7: 3 | N7: =IF(F7<>"",M7,0) -> 3 | O7: Range_2 | P7: {=IF(F7<>"",SUMPRODUCT(MAX((INDIRECT(ADDRESS(1,COLUMN(K$1),2) &":"& ADDRESS(ROW(),COLUMN(K$1),4))<>"")*(ROW(INDIRECT(ADDRESS(1,COLUMN(K$1),2) &":"& ADDRESS(ROW(),COLUMN(K$1),4)))))),239)} -> 3 | Q7: =IF(Y7<>"",VLOOKUP(Y7,INDIRECT(O7),2,0),"") | R7: =IF(Q7<>"",IF(F7<>"",Q7*M7,0),"") | S7: =IF(R7<>"",IF(R7<>0,R7*INDIRECT(ADDRESS(P7,COLUMN(K$1),4,)),0),"") | T7: =IF(R7<>"",R7/SUMIFS(M$3:M$253,P$3:P$253,P7),"") | U7: =IF(R7<>"",SUMIFS(T$3:T$253,P$3:P$253,P7),"") | V7: =IFERROR(INDEX(K:K,P7),0) -> 2 | W7: =ADDRESS(ROW(INDIRECT(O7)),COLUMN(INDIRECT(O7)),1,1,"Appoggio")&":"&ADDRESS(ROW(INDIRECT(O7))+ROWS(INDIRECT(O7))-1,COLUMN(INDIRECT(O7)),1,1) -> Appoggio!$A$17:$A$18 | X7: E' formalizzata in un documento?
B8: GSI.02 | C8: Politiche e procedure verticali collegate alla politica di alto livello | D8: ✔ | E8: ✔ | F8: ✔ | G8: =IF(L8>0,"✔","") -> ✔ | H8: A.5.1 | K8: 2 | L8: =IF(COUNTA(F8:F20)<>0,K8,0) -> 2 | M8: 3 | N8: =IF(F8<>"",M8,0) -> 3 | O8: Range_1 | P8: {=IF(F8<>"",SUMPRODUCT(MAX((INDIRECT(ADDRESS(1,COLUMN(K$1),2) &":"& ADDRESS(ROW(),COLUMN(K$1),4))<>"")*(ROW(INDIRECT(ADDRESS(1,COLUMN(K$1),2) &":"& ADDRESS(ROW(),COLUMN(K$1),4)))))),239)} -> 8 | Q8: =IF(Y8<>"",VLOOKUP(Y8,INDIRECT(O8),2,0),"") | R8: =IF(Q8<>"",IF(F8<>"",Q8*M8,0),"") | S8: =IF(R8<>"",IF(R8<>0,R8*INDIRECT(ADDRESS(P8,COLUMN(K$1),4,)),0),"") | T8: =IF(R8<>"",R8/SUMIFS(M$3:M$253,P$3:P$253,P8),"") | U8: =IF(R8<>"",SUMIFS(T$3:T$253,P$3:P$253,P8),"") | V8: =IFERROR(INDEX(K:K,P8),0) -> 2 | W8: =ADDRESS(ROW(INDIRECT(O8)),COLUMN(INDIRECT(O8)),1,1,"Appoggio")&":"&ADDRESS(ROW(INDIRECT(O8))+ROWS(INDIRECT(O8))-1,COLUMN(INDIRECT(O8)),1,1) -> Appoggio!$A$11:$A$13 | X8: La gestione degli incidenti è indirizzata?
D9: ✔ | E9: ✔ | F9: ✔ | I9: PR.AC-2 | J9: PR.AA-06 | M9: 3 | N9: =IF(F9<>"",M9,0) -> 3 | O9: Range_1 | P9: {=IF(F9<>"",SUMPRODUCT(MAX((INDIRECT(ADDRESS(1,COLUMN(K$1),2) &":"& ADDRESS(ROW(),COLUMN(K$1),4))<>"")*(ROW(INDIRECT(ADDRESS(1,COLUMN(K$1),2) &":"& ADDRESS(ROW(),COLUMN(K$1),4)))))),239)} -> 8 | Q9: =IF(Y9<>"",VLOOKUP(Y9,INDIRECT(O9),2,0),"") | R9: =IF(Q9<>"",IF(F9<>"",Q9*M9,0),"") | S9: =IF(R9<>"",IF(R9<>0,R9*INDIRECT(ADDRESS(P9,COLUMN(K$1),4,)),0),"") | T9: =IF(R9<>"",R9/SUMIFS(M$3:M$253,P$3:P$253,P9),"") | U9: =IF(R9<>"",SUMIFS(T$3:T$253,P$3:P$253,P9),"") | V9: =IFERROR(INDEX(K:K,P9),0) -> 2 | W9: =ADDRESS(ROW(INDIRECT(O9)),COLUMN(INDIRECT(O9)),1,1,"Appoggio")&":"&ADDRESS(ROW(INDIRECT(O9))+ROWS(INDIRECT(O9))-1,COLUMN(INDIRECT(O9)),1,1) -> Appoggio!$A$11:$A$13 | X9: Il controllo degli accessi fisici è indirizzato?
D10: ✔ | E10: ✔ | F10: ✔ | I10: PR.AC-1 | J10: PR.AA-01 PR.AA-05 | M10: 3 | N10: =IF(F10<>"",M10,0) -> 3 | O10: Range_1 | P10: {=IF(F10<>"",SUMPRODUCT(MAX((INDIRECT(ADDRESS(1,COLUMN(K$1),2) &":"& ADDRESS(ROW(),COLUMN(K$1),4))<>"")*(ROW(INDIRECT(ADDRESS(1,COLUMN(K$1),2) &":"& ADDRESS(ROW(),COLUMN(K$1),4)))))),239)} -> 8 | Q10: =IF(Y10<>"",VLOOKUP(Y10,INDIRECT(O10),2,0),"") | R10: =IF(Q10<>"",IF(F10<>"",Q10*M10,0),"") | S10: =IF(R10<>"",IF(R10<>0,R10*INDIRECT(ADDRESS(P10,COLUMN(K$1),4,)),0),"") | T10: =IF(R10<>"",R10/SUMIFS(M$3:M$253,P$3:P$253,P10),"") | U10: =IF(R10<>"",SUMIFS(T$3:T$253,P$3:P$253,P10),"") | V10: =IFERROR(INDEX(K:K,P10),0) -> 2 | W10: =ADDRESS(ROW(INDIRECT(O10)),COLUMN(INDIRECT(O10)),1,1,"Appoggio")&":"&ADDRESS(ROW(INDIRECT(O10))+ROWS(INDIRECT(O10))-1,COLUMN(INDIRECT(O10)),1,1) -> Appoggio!$A$11:$A$13 | X10: Il controllo degli accessi logici è indirizzato?
D11: ✔ | E11: ✔ | F11: ✔ | M11: 2 | N11: =IF(F11<>"",M11,0) -> 2 | O11: Range_1 | P11: {=IF(F11<>"",SUMPRODUCT(MAX((INDIRECT(ADDRESS(1,COLUMN(K$1),2) &":"& ADDRESS(ROW(),COLUMN(K$1),4))<>"")*(ROW(INDIRECT(ADDRESS(1,COLUMN(K$1),2) &":"& ADDRESS(ROW(),COLUMN(K$1),4)))))),239)} -> 8 | Q11: =IF(Y11<>"",VLOOKUP(Y11,INDIRECT(O11),2,0),"") | R11: =IF(Q11<>"",IF(F11<>"",Q11*M11,0),"") | S11: =IF(R11<>"",IF(R11<>0,R11*INDIRECT(ADDRESS(P11,COLUMN(K$1),4,)),0),"") | T11: =IF(R11<>"",R11/SUMIFS(M$3:M$253,P$3:P$253,P11),"") | U11: =IF(R11<>"",SUMIFS(T$3:T$253,P$3:P$253,P11),"") | V11: =IFERROR(INDEX(K:K,P11),0) -> 2 | W11: =ADDRESS(ROW(INDIRECT(O11)),COLUMN(INDIRECT(O11)),1,1,"Appoggio")&":"&ADDRESS(ROW(INDIRECT(O11))+ROWS(INDIRECT(O11))-1,COLUMN(INDIRECT(O11)),1,1) -> Appoggio!$A$11:$A$13 | X11: L'uso accettabile delle risorse IT è indirizzato?
D12: ✔ | E12: ✔ | F12: ✔ | M12: 3 | N12: =IF(F12<>"",M12,0) -> 3 | O12: Range_1 | P12: {=IF(F12<>"",SUMPRODUCT(MAX((INDIRECT(ADDRESS(1,COLUMN(K$1),2) &":"& ADDRESS(ROW(),COLUMN(K$1),4))<>"")*(ROW(INDIRECT(ADDRESS(1,COLUMN(K$1),2) &":"& ADDRESS(ROW(),COLUMN(K$1),4)))))),239)} -> 8 | Q12: =IF(Y12<>"",VLOOKUP(Y12,INDIRECT(O12),2,0),"") | R12: =IF(Q12<>"",IF(F12<>"",Q12*M12,0),"") | S12: =IF(R12<>"",IF(R12<>0,R12*INDIRECT(ADDRESS(P12,COLUMN(K$1),4,)),0),"") | T12: =IF(R12<>"",R12/SUMIFS(M$3:M$253,P$3:P$253,P12),"") | U12: =IF(R12<>"",SUMIFS(T$3:T$253,P$3:P$253,P12),"") | V12: =IFERROR(INDEX(K:K,P12),0) -> 2 | W12: =ADDRESS(ROW(INDIRECT(O12)),COLUMN(INDIRECT(O12)),1,1,"Appoggio")&":"&ADDRESS(ROW(INDIRECT(O12))+ROWS(INDIRECT(O12))-1,COLUMN(INDIRECT(O12)),1,1) -> Appoggio!$A$11:$A$13 | X12: La gestione degli aggiornamenti è indirizzata?
D13: ✔ | E13: ✔ | F13: ✔ | I13: PR.IP-1 | J13: PR.PS-01 | M13: 2 | N13: =IF(F13<>"",M13,0) -> 2 | O13: Range_1 | P13: {=IF(F13<>"",SUMPRODUCT(MAX((INDIRECT(ADDRESS(1,COLUMN(K$1),2) &":"& ADDRESS(ROW(),COLUMN(K$1),4))<>"")*(ROW(INDIRECT(ADDRESS(1,COLUMN(K$1),2) &":"& ADDRESS(ROW(),COLUMN(K$1),4)))))),239)} -> 8 | Q13: =IF(Y13<>"",VLOOKUP(Y13,INDIRECT(O13),2,0),"") | R13: =IF(Q13<>"",IF(F13<>"",Q13*M13,0),"") | S13: =IF(R13<>"",IF(R13<>0,R13*INDIRECT(ADDRESS(P13,COLUMN(K$1),4,)),0),"") | T13: =IF(R13<>"",R13/SUMIFS(M$3:M$253,P$3:P$253,P13),"") | U13: =IF(R13<>"",SUMIFS(T$3:T$253,P$3:P$253,P13),"") | V13: =IFERROR(INDEX(K:K,P13),0) -> 2 | W13: =ADDRESS(ROW(INDIRECT(O13)),COLUMN(INDIRECT(O13)),1,1,"Appoggio")&":"&ADDRESS(ROW(INDIRECT(O13))+ROWS(INDIRECT(O13))-1,COLUMN(INDIRECT(O13)),1,1) -> Appoggio!$A$11:$A$13 | X13: La gestione dei cambiamenti è indirizzata?
D14: ✔ | E14: ✔ | F14: ✔ | M14: 2 | N14: =IF(F14<>"",M14,0) -> 2 | O14: Range_2 | P14: {=IF(F14<>"",SUMPRODUCT(MAX((INDIRECT(ADDRESS(1,COLUMN(K$1),2) &":"& ADDRESS(ROW(),COLUMN(K$1),4))<>"")*(ROW(INDIRECT(ADDRESS(1,COLUMN(K$1),2) &":"& ADDRESS(ROW(),COLUMN(K$1),4)))))),239)} -> 8 | Q14: =IF(Y14<>"",VLOOKUP(Y14,INDIRECT(O14),2,0),"") | R14: =IF(Q14<>"",IF(F14<>"",Q14*M14,0),"") | S14: =IF(R14<>"",IF(R14<>0,R14*INDIRECT(ADDRESS(P14,COLUMN(K$1),4,)),0),"") | T14: =IF(R14<>"",R14/SUMIFS(M$3:M$253,P$3:P$253,P14),"") | U14: =IF(R14<>"",SUMIFS(T$3:T$253,P$3:P$253,P14),"") | V14: =IFERROR(INDEX(K:K,P14),0) -> 2 | W14: =ADDRESS(ROW(INDIRECT(O14)),COLUMN(INDIRECT(O14)),1,1,"Appoggio")&":"&ADDRESS(ROW(INDIRECT(O14))+ROWS(INDIRECT(O14))-1,COLUMN(INDIRECT(O14)),1,1) -> Appoggio!$A$17:$A$18 | X14: Lo sviluppo sicuro del software è indirizzato?
D15: ✔ | E15: ✔ | F15: ✔ | I15: PR.IP-2 | J15: PR.PS-06 ID.AM-08 | M15: 1 | N15: =IF(F15<>"",M15,0) -> 1 | O15: Range_1 | P15: {=IF(F15<>"",SUMPRODUCT(MAX((INDIRECT(ADDRESS(1,COLUMN(K$1),2) &":"& ADDRESS(ROW(),COLUMN(K$1),4))<>"")*(ROW(INDIRECT(ADDRESS(1,COLUMN(K$1),2) &":"& ADDRESS(ROW(),COLUMN(K$1),4)))))),239)} -> 8 | Q15: =IF(Y15<>"",VLOOKUP(Y15,INDIRECT(O15),2,0),"") | R15: =IF(Q15<>"",IF(F15<>"",Q15*M15,0),"") | S15: =IF(R15<>"",IF(R15<>0,R15*INDIRECT(ADDRESS(P15,COLUMN(K$1),4,)),0),"") | T15: =IF(R15<>"",R15/SUMIFS(M$3:M$253,P$3:P$253,P15),"") | U15: =IF(R15<>"",SUMIFS(T$3:T$253,P$3:P$253,P15),"") | V15: =IFERROR(INDEX(K:K,P15),0) -> 2 | W15: =ADDRESS(ROW(INDIRECT(O15)),COLUMN(INDIRECT(O15)),1,1,"Appoggio")&":"&ADDRESS(ROW(INDIRECT(O15))+ROWS(INDIRECT(O15))-1,COLUMN(INDIRECT(O15)),1,1) -> Appoggio!$A$11:$A$13 | X15: La gestione del ciclo di vita dei sistemi è indirizzata?
D16: ✔ | E16: ✔ | F16: ✔ | I16: ID.AM-5 | J16: ID.AM-05 | M16: 2 | N16: =IF(F16<>"",M16,0) -> 2 | O16: Range_1 | P16: {=IF(F16<>"",SUMPRODUCT(MAX((INDIRECT(ADDRESS(1,COLUMN(K$1),2) &":"& ADDRESS(ROW(),COLUMN(K$1),4))<>"")*(ROW(INDIRECT(ADDRESS(1,COLUMN(K$1),2) &":"& ADDRESS(ROW(),COLUMN(K$1),4)))))),239)} -> 8 | Q16: =IF(Y16<>"",VLOOKUP(Y16,INDIRECT(O16),2,0),"") | R16: =IF(Q16<>"",IF(F16<>"",Q16*M16,0),"") | S16: =IF(R16<>"",IF(R16<>0,R16*INDIRECT(ADDRESS(P16,COLUMN(K$1),4,)),0),"") | T16: =IF(R16<>"",R16/SUMIFS(M$3:M$253,P$3:P$253,P16),"") | U16: =IF(R16<>"",SUMIFS(T$3:T$253,P$3:P$253,P16),"") | V16: =IFERROR(INDEX(K:K,P16),0) -> 2 | W16: =ADDRESS(ROW(INDIRECT(O16)),COLUMN(INDIRECT(O16)),1,1,"Appoggio")&":"&ADDRESS(ROW(INDIRECT(O16))+ROWS(INDIRECT(O16))-1,COLUMN(INDIRECT(O16)),1,1) -> Appoggio!$A$11:$A$13 | X16: La classificazione delle informazioni è indirizzata?
D17: ✔ | E17: ✔ | F17: ✔ | I17: PR.PT-1 | J17: PR.PS-04 | M17: 2 | N17: =IF(F17<>"",M17,0) -> 2 | O17: Range_1 | P17: {=IF(F17<>"",SUMPRODUCT(MAX((INDIRECT(ADDRESS(1,COLUMN(K$1),2) &":"& ADDRESS(ROW(),COLUMN(K$1),4))<>"")*(ROW(INDIRECT(ADDRESS(1,COLUMN(K$1),2) &":"& ADDRESS(ROW(),COLUMN(K$1),4)))))),239)} -> 8 | Q17: =IF(Y17<>"",VLOOKUP(Y17,INDIRECT(O17),2,0),"") | R17: =IF(Q17<>"",IF(F17<>"",Q17*M17,0),"") | S17: =IF(R17<>"",IF(R17<>0,R17*INDIRECT(ADDRESS(P17,COLUMN(K$1),4,)),0),"") | T17: =IF(R17<>"",R17/SUMIFS(M$3:M$253,P$3:P$253,P17),"") | U17: =IF(R17<>"",SUMIFS(T$3:T$253,P$3:P$253,P17),"") | V17: =IFERROR(INDEX(K:K,P17),0) -> 2 | W17: =ADDRESS(ROW(INDIRECT(O17)),COLUMN(INDIRECT(O17)),1,1,"Appoggio")&":"&ADDRESS(ROW(INDIRECT(O17))+ROWS(INDIRECT(O17))-1,COLUMN(INDIRECT(O17)),1,1) -> Appoggio!$A$11:$A$13 | X17: La gestione dei log è indirizzata?
D18: ✔ | E18: ✔ | F18: ✔ | I18: DP-ID.DM-1 | J18: DP-ID.DM-01 | M18: 1 | N18: =IF(F18<>"",M18,0) -> 1 | O18: Range_1 | P18: {=IF(F18<>"",SUMPRODUCT(MAX((INDIRECT(ADDRESS(1,COLUMN(K$1),2) &":"& ADDRESS(ROW(),COLUMN(K$1),4))<>"")*(ROW(INDIRECT(ADDRESS(1,COLUMN(K$1),2) &":"& ADDRESS(ROW(),COLUMN(K$1),4)))))),239)} -> 8 | Q18: =IF(Y18<>"",VLOOKUP(Y18,INDIRECT(O18),2,0),"") | R18: =IF(Q18<>"",IF(F18<>"",Q18*M18,0),"") | S18: =IF(R18<>"",IF(R18<>0,R18*INDIRECT(ADDRESS(P18,COLUMN(K$1),4,)),0),"") | T18: =IF(R18<>"",R18/SUMIFS(M$3:M$253,P$3:P$253,P18),"") | U18: =IF(R18<>"",SUMIFS(T$3:T$253,P$3:P$253,P18),"") | V18: =IFERROR(INDEX(K:K,P18),0) -> 2 | W18: =ADDRESS(ROW(INDIRECT(O18)),COLUMN(INDIRECT(O18)),1,1,"Appoggio")&":"&ADDRESS(ROW(INDIRECT(O18))+ROWS(INDIRECT(O18))-1,COLUMN(INDIRECT(O18)),1,1) -> Appoggio!$A$11:$A$13 | X18: Il ciclo di vita dei dati è indirizzato?
D19: ✔ | E19: ✔ | F19: ✔ | I19: ID.SC-1 | J19: GV.SC-01 GV.SC-06 GV.SC-09 GV.SC-10 GV.RM-05 | M19: 2 | N19: =IF(F19<>"",M19,0) -> 2 | O19: Range_1 | P19: {=IF(F19<>"",SUMPRODUCT(MAX((INDIRECT(ADDRESS(1,COLUMN(K$1),2) &":"& ADDRESS(ROW(),COLUMN(K$1),4))<>"")*(ROW(INDIRECT(ADDRESS(1,COLUMN(K$1),2) &":"& ADDRESS(ROW(),COLUMN(K$1),4)))))),239)} -> 8 | Q19: =IF(Y19<>"",VLOOKUP(Y19,INDIRECT(O19),2,0),"") | R19: =IF(Q19<>"",IF(F19<>"",Q19*M19,0),"") | S19: =IF(R19<>"",IF(R19<>0,R19*INDIRECT(ADDRESS(P19,COLUMN(K$1),4,)),0),"") | T19: =IF(R19<>"",R19/SUMIFS(M$3:M$253,P$3:P$253,P19),"") | U19: =IF(R19<>"",SUMIFS(T$3:T$253,P$3:P$253,P19),"") | V19: =IFERROR(INDEX(K:K,P19),0) -> 2 | W19: =ADDRESS(ROW(INDIRECT(O19)),COLUMN(INDIRECT(O19)),1,1,"Appoggio")&":"&ADDRESS(ROW(INDIRECT(O19))+ROWS(INDIRECT(O19))-1,COLUMN(INDIRECT(O19)),1,1) -> Appoggio!$A$11:$A$13 | X19: La gestione dei fornitori è indirizzata?
D20: ✔ | E20: ✔ | F20: ✔ | J20: RC.CO-03 | M20: 1 | N20: =IF(F20<>"",M20,0) -> 1 | O20: Range_2 | P20: {=IF(F20<>"",SUMPRODUCT(MAX((INDIRECT(ADDRESS(1,COLUMN(K$1),2) &":"& ADDRESS(ROW(),COLUMN(K$1),4))<>"")*(ROW(INDIRECT(ADDRESS(1,COLUMN(K$1),2) &":"& ADDRESS(ROW(),COLUMN(K$1),4)))))),239)} -> 8 | Q20: =IF(Y20<>"",VLOOKUP(Y20,INDIRECT(O20),2,0),"") | R20: =IF(Q20<>"",IF(F20<>"",Q20*M20,0),"") | S20: =IF(R20<>"",IF(R20<>0,R20*INDIRECT(ADDRESS(P20,COLUMN(K$1),4,)),0),"") | T20: =IF(R20<>"",R20/SUMIFS(M$3:M$253,P$3:P$253,P20),"") | U20: =IF(R20<>"",SUMIFS(T$3:T$253,P$3:P$253,P20),"") | V20: =IFERROR(INDEX(K:K,P20),0) -> 2 | W20: =ADDRESS(ROW(INDIRECT(O20)),COLUMN(INDIRECT(O20)),1,1,"Appoggio")&":"&ADDRESS(ROW(INDIRECT(O20))+ROWS(INDIRECT(O20))-1,COLUMN(INDIRECT(O20)),1,1) -> Appoggio!$A$17:$A$18 | X20: Sono riesaminate ed eventualmente aggiornate almeno annualmente o in caso di cambiamenti significativi?
B21: GSI.03 | C21: Piano per la gestione della continuità operativa | D21: ✔ | F21: ✔ | G21: =IF(L21>0,"✔","") -> ✔ | H21: A.5.30 | I21: PR.IP-9 PR.IP-10 RC.RP-1 RC.IM-1 RC.IM-2 | J21: ID.IM-02 ID.IM-03 ID.IM-04 RS.MA-05 RC.RP-01 RC.RP-02 | K21: 1 | L21: =IF(COUNTA(F21:F24)<>0,K21,0) -> 1 | M21: 3 | N21: =IF(F21<>"",M21,0) -> 3 | O21: Range_1 | P21: {=IF(F21<>"",SUMPRODUCT(MAX((INDIRECT(ADDRESS(1,COLUMN(K$1),2) &":"& ADDRESS(ROW(),COLUMN(K$1),4))<>"")*(ROW(INDIRECT(ADDRESS(1,COLUMN(K$1),2) &":"& ADDRESS(ROW(),COLUMN(K$1),4)))))),239)} -> 21 | Q21: =IF(Y21<>"",VLOOKUP(Y21,INDIRECT(O21),2,0),"") | R21: =IF(Q21<>"",IF(F21<>"",Q21*M21,0),"") | S21: =IF(R21<>"",IF(R21<>0,R21*INDIRECT(ADDRESS(P21,COLUMN(K$1),4,)),0),"") | T21: =IF(R21<>"",R21/SUMIFS(M$3:M$253,P$3:P$253,P21),"") | U21: =IF(R21<>"",SUMIFS(T$3:T$253,P$3:P$253,P21),"") | V21: =IFERROR(INDEX(K:K,P21),0) -> 1 | W21: =ADDRESS(ROW(INDIRECT(O21)),COLUMN(INDIRECT(O21)),1,1,"Appoggio")&":"&ADDRESS(ROW(INDIRECT(O21))+ROWS(INDIRECT(O21))-1,COLUMN(INDIRECT(O21)),1,1) -> Appoggio!$A$11:$A$13 | X21: Viene testato con periodicità almeno annuale?
D22: ✔ | F22: ✔ | M22: 2 | N22: =IF(F22<>"",M22,0) -> 2 | O22: Range_1 | P22: {=IF(F22<>"",SUMPRODUCT(MAX((INDIRECT(ADDRESS(1,COLUMN(K$1),2) &":"& ADDRESS(ROW(),COLUMN(K$1),4))<>"")*(ROW(INDIRECT(ADDRESS(1,COLUMN(K$1),2) &":"& ADDRESS(ROW(),COLUMN(K$1),4)))))),239)} -> 21 | Q22: =IF(Y22<>"",VLOOKUP(Y22,INDIRECT(O22),2,0),"") | R22: =IF(Q22<>"",IF(F22<>"",Q22*M22,0),"") | S22: =IF(R22<>"",IF(R22<>0,R22*INDIRECT(ADDRESS(P22,COLUMN(K$1),4,)),0),"") | T22: =IF(R22<>"",R22/SUMIFS(M$3:M$253,P$3:P$253,P22),"") | U22: =IF(R22<>"",SUMIFS(T$3:T$253,P$3:P$253,P22),"") | V22: =IFERROR(INDEX(K:K,P22),0) -> 1 | W22: =ADDRESS(ROW(INDIRECT(O22)),COLUMN(INDIRECT(O22)),1,1,"Appoggio")&":"&ADDRESS(ROW(INDIRECT(O22))+ROWS(INDIRECT(O22))-1,COLUMN(INDIRECT(O22)),1,1) -> Appoggio!$A$11:$A$13 | X22: Include la parte IT con una Business Impact Analysis ad esso relativa?
D23: ✔ | F23: ✔ | M23: 2 | N23: =IF(F23<>"",M23,0) -> 2 | O23: Range_1 | P23: {=IF(F23<>"",SUMPRODUCT(MAX((INDIRECT(ADDRESS(1,COLUMN(K$1),2) &":"& ADDRESS(ROW(),COLUMN(K$1),4))<>"")*(ROW(INDIRECT(ADDRESS(1,COLUMN(K$1),2) &":"& ADDRESS(ROW(),COLUMN(K$1),4)))))),239)} -> 21 | Q23: =IF(Y23<>"",VLOOKUP(Y23,INDIRECT(O23),2,0),"") | R23: =IF(Q23<>"",IF(F23<>"",Q23*M23,0),"") | S23: =IF(R23<>"",IF(R23<>0,R23*INDIRECT(ADDRESS(P23,COLUMN(K$1),4,)),0),"") | T23: =IF(R23<>"",R23/SUMIFS(M$3:M$253,P$3:P$253,P23),"") | U23: =IF(R23<>"",SUMIFS(T$3:T$253,P$3:P$253,P23),"") | V23: =IFERROR(INDEX(K:K,P23),0) -> 1 | W23: =ADDRESS(ROW(INDIRECT(O23)),COLUMN(INDIRECT(O23)),1,1,"Appoggio")&":"&ADDRESS(ROW(INDIRECT(O23))+ROWS(INDIRECT(O23))-1,COLUMN(INDIRECT(O23)),1,1) -> Appoggio!$A$11:$A$13 | X23: Prevede un piano di disaster recovery per i servizi critici?
D24: ✔ | F24: ✔ | M24: 3 | N24: =IF(F24<>"",M24,0) -> 3 | O24: Range_1 | P24: {=IF(F24<>"",SUMPRODUCT(MAX((INDIRECT(ADDRESS(1,COLUMN(K$1),2) &":"& ADDRESS(ROW(),COLUMN(K$1),4))<>"")*(ROW(INDIRECT(ADDRESS(1,COLUMN(K$1),2) &":"& ADDRESS(ROW(),COLUMN(K$1),4)))))),239)} -> 21 | Q24: =IF(Y24<>"",VLOOKUP(Y24,INDIRECT(O24),2,0),"") | R24: =IF(Q24<>"",IF(F24<>"",Q24*M24,0),"") | S24: =IF(R24<>"",IF(R24<>0,R24*INDIRECT(ADDRESS(P24,COLUMN(K$1),4,)),0),"") | T24: =IF(R24<>"",R24/SUMIFS(M$3:M$253,P$3:P$253,P24),"") | U24: =IF(R24<>"",SUMIFS(T$3:T$253,P$3:P$253,P24),"") | V24: =IFERROR(INDEX(K:K,P24),0) -> 1 | W24: =ADDRESS(ROW(INDIRECT(O24)),COLUMN(INDIRECT(O24)),1,1,"Appoggio")&":"&ADDRESS(ROW(INDIRECT(O24))+ROWS(INDIRECT(O24))-1,COLUMN(INDIRECT(O24)),1,1) -> Appoggio!$A$11:$A$13 | X24: E' mantenuto aggiornato almeno annualmente?
B25: GSI.04 | C25: Continuità operativa dei sistemi ICT | D25: ✔ | F25: ✔ | G25: =IF(L25>0,"✔","") -> ✔ | H25: A.5.30 | I25: PR.IP-4 | J25: PR.DS-11 | K25: 2 | L25: =IF(COUNTA(F25:F28)<>0,K25,0) -> 2 | M25: 3 | N25: =IF(F25<>"",M25,0) -> 3 | O25: Range_1 | P25: {=IF(F25<>"",SUMPRODUCT(MAX((INDIRECT(ADDRESS(1,COLUMN(K$1),2) &":"& ADDRESS(ROW(),COLUMN(K$1),4))<>"")*(ROW(INDIRECT(ADDRESS(1,COLUMN(K$1),2) &":"& ADDRESS(ROW(),COLUMN(K$1),4)))))),239)} -> 25 | Q25: =IF(Y25<>"",VLOOKUP(Y25,INDIRECT(O25),2,0),"") | R25: =IF(Q25<>"",IF(F25<>"",Q25*M25,0),"") | S25: =IF(R25<>"",IF(R25<>0,R25*INDIRECT(ADDRESS(P25,COLUMN(K$1),4,)),0),"") | T25: =IF(R25<>"",R25/SUMIFS(M$3:M$253,P$3:P$253,P25),"") | U25: =IF(R25<>"",SUMIFS(T$3:T$253,P$3:P$253,P25),"") | V25: =IFERROR(INDEX(K:K,P25),0) -> 2 | W25: =ADDRESS(ROW(INDIRECT(O25)),COLUMN(INDIRECT(O25)),1,1,"Appoggio")&":"&ADDRESS(ROW(INDIRECT(O25))+ROWS(INDIRECT(O25))-1,COLUMN(INDIRECT(O25)),1,1) -> Appoggio!$A$11:$A$13 | X25: E' assicurata tramite il mantenimento di una terza copia di backup dei dati in un sito remoto?
D26: ✔ | F26: ✔ | I26: PR.DS-4 | J26: PR.IR-04 | M26: 2 | N26: =IF(F26<>"",M26,0) -> 2 | O26: Range_1 | P26: {=IF(F26<>"",SUMPRODUCT(MAX((INDIRECT(ADDRESS(1,COLUMN(K$1),2) &":"& ADDRESS(ROW(),COLUMN(K$1),4))<>"")*(ROW(INDIRECT(ADDRESS(1,COLUMN(K$1),2) &":"& ADDRESS(ROW(),COLUMN(K$1),4)))))),239)} -> 25 | Q26: =IF(Y26<>"",VLOOKUP(Y26,INDIRECT(O26),2,0),"") | R26: =IF(Q26<>"",IF(F26<>"",Q26*M26,0),"") | S26: =IF(R26<>"",IF(R26<>0,R26*INDIRECT(ADDRESS(P26,COLUMN(K$1),4,)),0),"") | T26: =IF(R26<>"",R26/SUMIFS(M$3:M$253,P$3:P$253,P26),"") | U26: =IF(R26<>"",SUMIFS(T$3:T$253,P$3:P$253,P26),"") | V26: =IFERROR(INDEX(K:K,P26),0) -> 2 | W26: =ADDRESS(ROW(INDIRECT(O26)),COLUMN(INDIRECT(O26)),1,1,"Appoggio")&":"&ADDRESS(ROW(INDIRECT(O26))+ROWS(INDIRECT(O26))-1,COLUMN(INDIRECT(O26)),1,1) -> Appoggio!$A$11:$A$13 | X26: E' assicurata tramite l'allocazione di risorse dimensionate in modo da garantire sempre la disponibilità?
D27: ✔ | F27: ✔ | I27: PR.PT-5 | J27: PR.IR-03 | M27: 3 | N27: =IF(F27<>"",M27,0) -> 3 | O27: Range_1 | P27: {=IF(F27<>"",SUMPRODUCT(MAX((INDIRECT(ADDRESS(1,COLUMN(K$1),2) &":"& ADDRESS(ROW(),COLUMN(K$1),4))<>"")*(ROW(INDIRECT(ADDRESS(1,COLUMN(K$1),2) &":"& ADDRESS(ROW(),COLUMN(K$1),4)))))),239)} -> 25 | Q27: =IF(Y27<>"",VLOOKUP(Y27,INDIRECT(O27),2,0),"") | R27: =IF(Q27<>"",IF(F27<>"",Q27*M27,0),"") | S27: =IF(R27<>"",IF(R27<>0,R27*INDIRECT(ADDRESS(P27,COLUMN(K$1),4,)),0),"") | T27: =IF(R27<>"",R27/SUMIFS(M$3:M$253,P$3:P$253,P27),"") | U27: =IF(R27<>"",SUMIFS(T$3:T$253,P$3:P$253,P27),"") | V27: =IFERROR(INDEX(K:K,P27),0) -> 2 | W27: =ADDRESS(ROW(INDIRECT(O27)),COLUMN(INDIRECT(O27)),1,1,"Appoggio")&":"&ADDRESS(ROW(INDIRECT(O27))+ROWS(INDIRECT(O27))-1,COLUMN(INDIRECT(O27)),1,1) -> Appoggio!$A$11:$A$13 | X27: E' assicurata tramite la ridondanza locale di tutti i sistemi critici adottando soluzioni ad alta affidabilità?
D28: ✔ | F28: ✔ | I28: PR.IP-9 | J28: ID.IM-04 | M28: 2 | N28: =IF(F28<>"",M28,0) -> 2 | O28: Range_1 | P28: {=IF(F28<>"",SUMPRODUCT(MAX((INDIRECT(ADDRESS(1,COLUMN(K$1),2) &":"& ADDRESS(ROW(),COLUMN(K$1),4))<>"")*(ROW(INDIRECT(ADDRESS(1,COLUMN(K$1),2) &":"& ADDRESS(ROW(),COLUMN(K$1),4)))))),239)} -> 25 | Q28: =IF(Y28<>"",VLOOKUP(Y28,INDIRECT(O28),2,0),"") | R28: =IF(Q28<>"",IF(F28<>"",Q28*M28,0),"") | S28: =IF(R28<>"",IF(R28<>0,R28*INDIRECT(ADDRESS(P28,COLUMN(K$1),4,)),0),"") | T28: =IF(R28<>"",R28/SUMIFS(M$3:M$253,P$3:P$253,P28),"") | U28: =IF(R28<>"",SUMIFS(T$3:T$253,P$3:P$253,P28),"") | V28: =IFERROR(INDEX(K:K,P28),0) -> 2 | W28: =ADDRESS(ROW(INDIRECT(O28)),COLUMN(INDIRECT(O28)),1,1,"Appoggio")&":"&ADDRESS(ROW(INDIRECT(O28))+ROWS(INDIRECT(O28))-1,COLUMN(INDIRECT(O28)),1,1) -> Appoggio!$A$11:$A$13 | X28: E' assicurata tramite la ridondanza geografica di tutti i sistemi critici in un sito remoto situato a più di 50 km dal sito primario?
B29: GSI.05 | C29: Responsabilità in merito alla cybersecurity / sicurezza delle informazioni / sicurezza informatica | D29: ✔ | F29: ✔ | G29: =IF(L29>0,"✔","") -> ✔ | H29: A.5.2 | I29: ID.AM-6 ID.GV-2 DE.DP.1 RS.CO-1 | J29: GV.SC-02 GV.OC-02 GV.RR-02 PR.AT-01 | K29: 2 | L29: =IF(COUNTA(F29:F35)<>0,K29,0) -> 2 | M29: 3 | N29: =IF(F29<>"",M29,0) -> 3 | O29: Range_1 | P29: {=IF(F29<>"",SUMPRODUCT(MAX((INDIRECT(ADDRESS(1,COLUMN(K$1),2) &":"& ADDRESS(ROW(),COLUMN(K$1),4))<>"")*(ROW(INDIRECT(ADDRESS(1,COLUMN(K$1),2) &":"& ADDRESS(ROW(),COLUMN(K$1),4)))))),239)} -> 29 | Q29: =IF(Y29<>"",VLOOKUP(Y29,INDIRECT(O29),2,0),"") | R29: =IF(Q29<>"",IF(F29<>"",Q29*M29,0),"") | S29: =IF(R29<>"",IF(R29<>0,R29*INDIRECT(ADDRESS(P29,COLUMN(K$1),4,)),0),"") | T29: =IF(R29<>"",R29/SUMIFS(M$3:M$253,P$3:P$253,P29),"") | U29: =IF(R29<>"",SUMIFS(T$3:T$253,P$3:P$253,P29),"") | V29: =IFERROR(INDEX(K:K,P29),0) -> 2 | W29: =ADDRESS(ROW(INDIRECT(O29)),COLUMN(INDIRECT(O29)),1,1,"Appoggio")&":"&ADDRESS(ROW(INDIRECT(O29))+ROWS(INDIRECT(O29))-1,COLUMN(INDIRECT(O29)),1,1) -> Appoggio!$A$11:$A$13 | X29: Sono assegnate ad un Responsabile della Sicurezza delle Informazioni / Cybersecurity o CISO che riporta al responsabile IT o superiore?
D30: ✔ | F30: ✔ | M30: 2 | N30: =IF(F30<>"",M30,0) -> 2 | O30: Range_1 | P30: {=IF(F30<>"",SUMPRODUCT(MAX((INDIRECT(ADDRESS(1,COLUMN(K$1),2) &":"& ADDRESS(ROW(),COLUMN(K$1),4))<>"")*(ROW(INDIRECT(ADDRESS(1,COLUMN(K$1),2) &":"& ADDRESS(ROW(),COLUMN(K$1),4)))))),239)} -> 29 | Q30: =IF(Y30<>"",VLOOKUP(Y30,INDIRECT(O30),2,0),"") | R30: =IF(Q30<>"",IF(F30<>"",Q30*M30,0),"") | S30: =IF(R30<>"",IF(R30<>0,R30*INDIRECT(ADDRESS(P30,COLUMN(K$1),4,)),0),"") | T30: =IF(R30<>"",R30/SUMIFS(M$3:M$253,P$3:P$253,P30),"") | U30: =IF(R30<>"",SUMIFS(T$3:T$253,P$3:P$253,P30),"") | V30: =IFERROR(INDEX(K:K,P30),0) -> 2 | W30: =ADDRESS(ROW(INDIRECT(O30)),COLUMN(INDIRECT(O30)),1,1,"Appoggio")&":"&ADDRESS(ROW(INDIRECT(O30))+ROWS(INDIRECT(O30))-1,COLUMN(INDIRECT(O30)),1,1) -> Appoggio!$A$11:$A$13 | X30: Sono assegnate a chi gestisce dei sistemi informativi per garantirne la protezione?
D31: ✔ | F31: ✔ | M31: 2 | N31: =IF(F31<>"",M31,0) -> 2 | O31: Range_1 | P31: {=IF(F31<>"",SUMPRODUCT(MAX((INDIRECT(ADDRESS(1,COLUMN(K$1),2) &":"& ADDRESS(ROW(),COLUMN(K$1),4))<>"")*(ROW(INDIRECT(ADDRESS(1,COLUMN(K$1),2) &":"& ADDRESS(ROW(),COLUMN(K$1),4)))))),239)} -> 29 | Q31: =IF(Y31<>"",VLOOKUP(Y31,INDIRECT(O31),2,0),"") | R31: =IF(Q31<>"",IF(F31<>"",Q31*M31,0),"") | S31: =IF(R31<>"",IF(R31<>0,R31*INDIRECT(ADDRESS(P31,COLUMN(K$1),4,)),0),"") | T31: =IF(R31<>"",R31/SUMIFS(M$3:M$253,P$3:P$253,P31),"") | U31: =IF(R31<>"",SUMIFS(T$3:T$253,P$3:P$253,P31),"") | V31: =IFERROR(INDEX(K:K,P31),0) -> 2 | W31: =ADDRESS(ROW(INDIRECT(O31)),COLUMN(INDIRECT(O31)),1,1,"Appoggio")&":"&ADDRESS(ROW(INDIRECT(O31))+ROWS(INDIRECT(O31))-1,COLUMN(INDIRECT(O31)),1,1) -> Appoggio!$A$11:$A$13 | X31: Sono assegnate a tutto il personale affinché le informazioni e i sistemi informativi siano utilizzati correttamente?
D32: ✔ | F32: ✔ | M32: 2 | N32: =IF(F32<>"",M32,0) -> 2 | O32: Range_1 | P32: {=IF(F32<>"",SUMPRODUCT(MAX((INDIRECT(ADDRESS(1,COLUMN(K$1),2) &":"& ADDRESS(ROW(),COLUMN(K$1),4))<>"")*(ROW(INDIRECT(ADDRESS(1,COLUMN(K$1),2) &":"& ADDRESS(ROW(),COLUMN(K$1),4)))))),239)} -> 29 | Q32: =IF(Y32<>"",VLOOKUP(Y32,INDIRECT(O32),2,0),"") | R32: =IF(Q32<>"",IF(F32<>"",Q32*M32,0),"") | S32: =IF(R32<>"",IF(R32<>0,R32*INDIRECT(ADDRESS(P32,COLUMN(K$1),4,)),0),"") | T32: =IF(R32<>"",R32/SUMIFS(M$3:M$253,P$3:P$253,P32),"") | U32: =IF(R32<>"",SUMIFS(T$3:T$253,P$3:P$253,P32),"") | V32: =IFERROR(INDEX(K:K,P32),0) -> 2 | W32: =ADDRESS(ROW(INDIRECT(O32)),COLUMN(INDIRECT(O32)),1,1,"Appoggio")&":"&ADDRESS(ROW(INDIRECT(O32))+ROWS(INDIRECT(O32))-1,COLUMN(INDIRECT(O32)),1,1) -> Appoggio!$A$11:$A$13 | X32: Sono assegnate alle terze parti che hanno un ruolo nella protezione delle informazioni?
D33: ✔ | F33: ✔ | M33: 2 | N33: =IF(F33<>"",M33,0) -> 2 | O33: Range_1 | P33: {=IF(F33<>"",SUMPRODUCT(MAX((INDIRECT(ADDRESS(1,COLUMN(K$1),2) &":"& ADDRESS(ROW(),COLUMN(K$1),4))<>"")*(ROW(INDIRECT(ADDRESS(1,COLUMN(K$1),2) &":"& ADDRESS(ROW(),COLUMN(K$1),4)))))),239)} -> 29 | Q33: =IF(Y33<>"",VLOOKUP(Y33,INDIRECT(O33),2,0),"") | R33: =IF(Q33<>"",IF(F33<>"",Q33*M33,0),"") | S33: =IF(R33<>"",IF(R33<>0,R33*INDIRECT(ADDRESS(P33,COLUMN(K$1),4,)),0),"") | T33: =IF(R33<>"",R33/SUMIFS(M$3:M$253,P$3:P$253,P33),"") | U33: =IF(R33<>"",SUMIFS(T$3:T$253,P$3:P$253,P33),"") | V33: =IFERROR(INDEX(K:K,P33),0) -> 2 | W33: =ADDRESS(ROW(INDIRECT(O33)),COLUMN(INDIRECT(O33)),1,1,"Appoggio")&":"&ADDRESS(ROW(INDIRECT(O33))+ROWS(INDIRECT(O33))-1,COLUMN(INDIRECT(O33)),1,1) -> Appoggio!$A$11:$A$13 | X33: Sono assegnate a chi deve intraprendere azioni specifiche in caso di emergenza o incidente?
D34: ✔ | F34: ✔ | M34: 2 | N34: =IF(F34<>"",M34,0) -> 2 | O34: Range_1 | P34: {=IF(F34<>"",SUMPRODUCT(MAX((INDIRECT(ADDRESS(1,COLUMN(K$1),2) &":"& ADDRESS(ROW(),COLUMN(K$1),4))<>"")*(ROW(INDIRECT(ADDRESS(1,COLUMN(K$1),2) &":"& ADDRESS(ROW(),COLUMN(K$1),4)))))),239)} -> 29 | Q34: =IF(Y34<>"",VLOOKUP(Y34,INDIRECT(O34),2,0),"") | R34: =IF(Q34<>"",IF(F34<>"",Q34*M34,0),"") | S34: =IF(R34<>"",IF(R34<>0,R34*INDIRECT(ADDRESS(P34,COLUMN(K$1),4,)),0),"") | T34: =IF(R34<>"",R34/SUMIFS(M$3:M$253,P$3:P$253,P34),"") | U34: =IF(R34<>"",SUMIFS(T$3:T$253,P$3:P$253,P34),"") | V34: =IFERROR(INDEX(K:K,P34),0) -> 2 | W34: =ADDRESS(ROW(INDIRECT(O34)),COLUMN(INDIRECT(O34)),1,1,"Appoggio")&":"&ADDRESS(ROW(INDIRECT(O34))+ROWS(INDIRECT(O34))-1,COLUMN(INDIRECT(O34)),1,1) -> Appoggio!$A$11:$A$13 | X34: Sono assegnate a chi deve monitorare i sistemi informativi?
D35: ✔ | F35: ✔ | M35: 2 | N35: =IF(F35<>"",M35,0) -> 2 | O35: Range_1 | P35: {=IF(F35<>"",SUMPRODUCT(MAX((INDIRECT(ADDRESS(1,COLUMN(K$1),2) &":"& ADDRESS(ROW(),COLUMN(K$1),4))<>"")*(ROW(INDIRECT(ADDRESS(1,COLUMN(K$1),2) &":"& ADDRESS(ROW(),COLUMN(K$1),4)))))),239)} -> 29 | Q35: =IF(Y35<>"",VLOOKUP(Y35,INDIRECT(O35),2,0),"") | R35: =IF(Q35<>"",IF(F35<>"",Q35*M35,0),"") | S35: =IF(R35<>"",IF(R35<>0,R35*INDIRECT(ADDRESS(P35,COLUMN(K$1),4,)),0),"") | T35: =IF(R35<>"",R35/SUMIFS(M$3:M$253,P$3:P$253,P35),"") | U35: =IF(R35<>"",SUMIFS(T$3:T$253,P$3:P$253,P35),"") | V35: =IFERROR(INDEX(K:K,P35),0) -> 2 | W35: =ADDRESS(ROW(INDIRECT(O35)),COLUMN(INDIRECT(O35)),1,1,"Appoggio")&":"&ADDRESS(ROW(INDIRECT(O35))+ROWS(INDIRECT(O35))-1,COLUMN(INDIRECT(O35)),1,1) -> Appoggio!$A$11:$A$13 | X35: Sono documentate e mantenute aggiornate?
B36: GSI.06 | C36: Responsabilità in merito alla protezione dei dati personali | D36: ✔ | F36: ✔ | G36: =IF(L36>0,"✔","") -> ✔ | H36: - | I36: DP-ID.AM-7 | J36: DP-GV.RR-05 | K36: 1 | L36: =IF(COUNTA(F36:F40)<>0,K36,0) -> 1 | M36: 3 | N36: =IF(F36<>"",M36,0) -> 3 | O36: Range_1 | P36: {=IF(F36<>"",SUMPRODUCT(MAX((INDIRECT(ADDRESS(1,COLUMN(K$1),2) &":"& ADDRESS(ROW(),COLUMN(K$1),4))<>"")*(ROW(INDIRECT(ADDRESS(1,COLUMN(K$1),2) &":"& ADDRESS(ROW(),COLUMN(K$1),4)))))),239)} -> 36 | Q36: =IF(Y36<>"",VLOOKUP(Y36,INDIRECT(O36),2,0),"") | R36: =IF(Q36<>"",IF(F36<>"",Q36*M36,0),"") | S36: =IF(R36<>"",IF(R36<>0,R36*INDIRECT(ADDRESS(P36,COLUMN(K$1),4,)),0),"") | T36: =IF(R36<>"",R36/SUMIFS(M$3:M$253,P$3:P$253,P36),"") | U36: =IF(R36<>"",SUMIFS(T$3:T$253,P$3:P$253,P36),"") | V36: =IFERROR(INDEX(K:K,P36),0) -> 1 | W36: =ADDRESS(ROW(INDIRECT(O36)),COLUMN(INDIRECT(O36)),1,1,"Appoggio")&":"&ADDRESS(ROW(INDIRECT(O36))+ROWS(INDIRECT(O36))-1,COLUMN(INDIRECT(O36)),1,1) -> Appoggio!$A$11:$A$13 | X36: Sono assegnate ad un Privacy Officer/Manager o equivalente?
D37: ✔ | F37: ✔ | M37: 2 | N37: =IF(F37<>"",M37,0) -> 2 | O37: Range_1 | P37: {=IF(F37<>"",SUMPRODUCT(MAX((INDIRECT(ADDRESS(1,COLUMN(K$1),2) &":"& ADDRESS(ROW(),COLUMN(K$1),4))<>"")*(ROW(INDIRECT(ADDRESS(1,COLUMN(K$1),2) &":"& ADDRESS(ROW(),COLUMN(K$1),4)))))),239)} -> 36 | Q37: =IF(Y37<>"",VLOOKUP(Y37,INDIRECT(O37),2,0),"") | R37: =IF(Q37<>"",IF(F37<>"",Q37*M37,0),"") | S37: =IF(R37<>"",IF(R37<>0,R37*INDIRECT(ADDRESS(P37,COLUMN(K$1),4,)),0),"") | T37: =IF(R37<>"",R37/SUMIFS(M$3:M$253,P$3:P$253,P37),"") | U37: =IF(R37<>"",SUMIFS(T$3:T$253,P$3:P$253,P37),"") | V37: =IFERROR(INDEX(K:K,P37),0) -> 1 | W37: =ADDRESS(ROW(INDIRECT(O37)),COLUMN(INDIRECT(O37)),1,1,"Appoggio")&":"&ADDRESS(ROW(INDIRECT(O37))+ROWS(INDIRECT(O37))-1,COLUMN(INDIRECT(O37)),1,1) -> Appoggio!$A$11:$A$13 | X37: Sono supportate dalla presenza di un Data Protection Officer?
D38: ✔ | F38: ✔ | M38: 2 | N38: =IF(F38<>"",M38,0) -> 2 | O38: Range_1 | P38: {=IF(F38<>"",SUMPRODUCT(MAX((INDIRECT(ADDRESS(1,COLUMN(K$1),2) &":"& ADDRESS(ROW(),COLUMN(K$1),4))<>"")*(ROW(INDIRECT(ADDRESS(1,COLUMN(K$1),2) &":"& ADDRESS(ROW(),COLUMN(K$1),4)))))),239)} -> 36 | Q38: =IF(Y38<>"",VLOOKUP(Y38,INDIRECT(O38),2,0),"") | R38: =IF(Q38<>"",IF(F38<>"",Q38*M38,0),"") | S38: =IF(R38<>"",IF(R38<>0,R38*INDIRECT(ADDRESS(P38,COLUMN(K$1),4,)),0),"") | T38: =IF(R38<>"",R38/SUMIFS(M$3:M$253,P$3:P$253,P38),"") | U38: =IF(R38<>"",SUMIFS(T$3:T$253,P$3:P$253,P38),"") | V38: =IFERROR(INDEX(K:K,P38),0) -> 1 | W38: =ADDRESS(ROW(INDIRECT(O38)),COLUMN(INDIRECT(O38)),1,1,"Appoggio")&":"&ADDRESS(ROW(INDIRECT(O38))+ROWS(INDIRECT(O38))-1,COLUMN(INDIRECT(O38)),1,1) -> Appoggio!$A$11:$A$13 | X38: Sono assegnate ai Dirigenti delle aree in cui sono trattati dati personali?
D39: ✔ | F39: ✔ | M39: 3 | N39: =IF(F39<>"",M39,0) -> 3 | O39: Range_1 | P39: {=IF(F39<>"",SUMPRODUCT(MAX((INDIRECT(ADDRESS(1,COLUMN(K$1),2) &":"& ADDRESS(ROW(),COLUMN(K$1),4))<>"")*(ROW(INDIRECT(ADDRESS(1,COLUMN(K$1),2) &":"& ADDRESS(ROW(),COLUMN(K$1),4)))))),239)} -> 36 | Q39: =IF(Y39<>"",VLOOKUP(Y39,INDIRECT(O39),2,0),"") | R39: =IF(Q39<>"",IF(F39<>"",Q39*M39,0),"") | S39: =IF(R39<>"",IF(R39<>0,R39*INDIRECT(ADDRESS(P39,COLUMN(K$1),4,)),0),"") | T39: =IF(R39<>"",R39/SUMIFS(M$3:M$253,P$3:P$253,P39),"") | U39: =IF(R39<>"",SUMIFS(T$3:T$253,P$3:P$253,P39),"") | V39: =IFERROR(INDEX(K:K,P39),0) -> 1 | W39: =ADDRESS(ROW(INDIRECT(O39)),COLUMN(INDIRECT(O39)),1,1,"Appoggio")&":"&ADDRESS(ROW(INDIRECT(O39))+ROWS(INDIRECT(O39))-1,COLUMN(INDIRECT(O39)),1,1) -> Appoggio!$A$11:$A$13 | X39: Sono assegnate alle terze parti che agiscono in qualità di Responsabili?
D40: ✔ | F40: ✔ | M40: 2 | N40: =IF(F40<>"",M40,0) -> 2 | O40: Range_1 | P40: {=IF(F40<>"",SUMPRODUCT(MAX((INDIRECT(ADDRESS(1,COLUMN(K$1),2) &":"& ADDRESS(ROW(),COLUMN(K$1),4))<>"")*(ROW(INDIRECT(ADDRESS(1,COLUMN(K$1),2) &":"& ADDRESS(ROW(),COLUMN(K$1),4)))))),239)} -> 36 | Q40: =IF(Y40<>"",VLOOKUP(Y40,INDIRECT(O40),2,0),"") | R40: =IF(Q40<>"",IF(F40<>"",Q40*M40,0),"") | S40: =IF(R40<>"",IF(R40<>0,R40*INDIRECT(ADDRESS(P40,COLUMN(K$1),4,)),0),"") | T40: =IF(R40<>"",R40/SUMIFS(M$3:M$253,P$3:P$253,P40),"") | U40: =IF(R40<>"",SUMIFS(T$3:T$253,P$3:P$253,P40),"") | V40: =IFERROR(INDEX(K:K,P40),0) -> 1 | W40: =ADDRESS(ROW(INDIRECT(O40)),COLUMN(INDIRECT(O40)),1,1,"Appoggio")&":"&ADDRESS(ROW(INDIRECT(O40))+ROWS(INDIRECT(O40))-1,COLUMN(INDIRECT(O40)),1,1) -> Appoggio!$A$11:$A$13 | X40: Sono documentate e mantenute aggiornate?
...

Sheet Risultati
A1: Risultati
A2: Questionario compilato da: | B2: <nome e cognome>
A3: Data di compilazione: | B3: <gg-mm-aaaa>
B4: valore assoluto | C4: percentuale
A5: Temi del questionario | B5: =COUNTIF(Questionario!B3:B253,"<>") -> 48
A6: Temi selezionati | B6: =COUNTIF(Questionario!G3:G253,"✔") -> 48 | C6: =B6/B5 -> 1
A7: Domande del questionario | B7: =COUNTA(Questionario!X3:X253) -> 251
A8: Domande selezionate | B8: =COUNTA(Questionario!F3:F253) -> 251 | C8: =B8/B7 -> 1
A9: Risposte fornite | B9: =ROWS(Questionario!Y3:Y253)-COUNTIF(Questionario!Y3:Y253,"") -> 0 | C9: =B9/B8 -> 0
A11: Totale ottenuto (TO) | B11: =SUMPRODUCT(Questionario!T3:T253,Questionario!V3:V253) -> 0
A12: Massimo ottenibile (TM) | B12: =SUM(Questionario!L3:L253) -> 65
A13: Punteggio finale ottenuto | C13: =B11/B12 -> 0

Sheet Appoggio
A3: Range_validi
A4: =A9 -> Range_1
A5: =A15 -> Range_2
A7: ✔
A9: Range_1 | D9: NOTA: tutte le formule sono state parametrizzate su 4096 righe, per evitare di avere fogli con righe e colonne infinite …
A10: risposta | B10: valore
A11: Sì | B11: 1
A12: Parziale | B12: 0.5
A13: No | B13: 0
A15: Range_2
A16: risposta | B16: valore
A17: Sì | B17: 1
A18: No | B18: 0
